<mujoco model="robot">
  <compiler angle="radian"/>
  <asset>
    <mesh name="fused_component_torso_1_hip_mount_1_collision_simple" file="fused_component_torso_1_hip_mount_1_collision_simple.stl"/>
    <mesh name="fused_component_full_arm_5_dof_2_lower_arm_1_dof_1_hand_1_slide_2_collision_simple" file="fused_component_full_arm_5_dof_2_lower_arm_1_dof_1_hand_1_slide_2_collision_simple.stl"/>
    <mesh name="fused_component_full_arm_5_dof_2_lower_arm_1_dof_1_hand_1_slide_1_collision_simple" file="fused_component_full_arm_5_dof_2_lower_arm_1_dof_1_hand_1_slide_1_collision_simple.stl"/>
    <mesh name="fused_component_full_arm_5_dof_1_lower_arm_1_dof_1_hand_1_slide_2_collision_simple" file="fused_component_full_arm_5_dof_1_lower_arm_1_dof_1_hand_1_slide_2_collision_simple.stl"/>
    <mesh name="fused_component_full_arm_5_dof_1_lower_arm_1_dof_1_hand_1_slide_1_collision_simple" file="fused_component_full_arm_5_dof_1_lower_arm_1_dof_1_hand_1_slide_1_collision_simple.stl"/>
    <mesh name="fused_component_full_arm_5_dof_2_lower_arm_1_dof_1_rmd_x4_24_mock_2_outer_rmd_x4_24_1_collision_simple" file="fused_component_full_arm_5_dof_2_lower_arm_1_dof_1_rmd_x4_24_mock_2_outer_rmd_x4_24_1_collision_simple.stl"/>
    <mesh name="fused_component_full_arm_5_dof_1_lower_arm_1_dof_1_rmd_x4_24_mock_2_outer_rmd_x4_24_1_collision_simple" file="fused_component_full_arm_5_dof_1_lower_arm_1_dof_1_rmd_x4_24_mock_2_outer_rmd_x4_24_1_collision_simple.stl"/>
    <mesh name="fused_component_full_arm_5_dof_2_upper_left_arm_1_rmd_x4_24_mock_2_inner_rmd_x4_24_1_collision_simple" file="fused_component_full_arm_5_dof_2_upper_left_arm_1_rmd_x4_24_mock_2_inner_rmd_x4_24_1_collision_simple.stl"/>
    <mesh name="fused_component_full_arm_5_dof_1_upper_left_arm_1_rmd_x4_24_mock_2_inner_rmd_x4_24_1_collision_simple" file="fused_component_full_arm_5_dof_1_upper_left_arm_1_rmd_x4_24_mock_2_inner_rmd_x4_24_1_collision_simple.stl"/>
    <mesh name="fused_component_full_arm_5_dof_2_upper_left_arm_1_rmd_x4_24_mock_1_outer_rmd_x4_24_1_collision_simple" file="fused_component_full_arm_5_dof_2_upper_left_arm_1_rmd_x4_24_mock_1_outer_rmd_x4_24_1_collision_simple.stl"/>
    <mesh name="fused_component_full_arm_5_dof_1_upper_left_arm_1_rmd_x4_24_mock_1_outer_rmd_x4_24_1_collision_simple" file="fused_component_full_arm_5_dof_1_upper_left_arm_1_rmd_x4_24_mock_1_outer_rmd_x4_24_1_collision_simple.stl"/>
    <mesh name="fused_component_full_arm_5_dof_2_upper_left_arm_1_rmd_x8_90_mock_2_inner_rmd_x8_90_1_collision_simple" file="fused_component_full_arm_5_dof_2_upper_left_arm_1_rmd_x8_90_mock_2_inner_rmd_x8_90_1_collision_simple.stl"/>
    <mesh name="fused_component_full_arm_5_dof_1_upper_left_arm_1_rmd_x8_90_mock_2_inner_rmd_x8_90_1_collision_simple" file="fused_component_full_arm_5_dof_1_upper_left_arm_1_rmd_x8_90_mock_2_inner_rmd_x8_90_1_collision_simple.stl"/>
    <mesh name="fused_component_full_arm_5_dof_2_upper_left_arm_1_rmd_x8_90_mock_1_inner_rmd_x8_90_1_collision_simple" file="fused_component_full_arm_5_dof_2_upper_left_arm_1_rmd_x8_90_mock_1_inner_rmd_x8_90_1_collision_simple.stl"/>
    <mesh name="fused_component_full_arm_5_dof_1_upper_left_arm_1_rmd_x8_90_mock_1_inner_rmd_x8_90_1_collision_simple" file="fused_component_full_arm_5_dof_1_upper_left_arm_1_rmd_x8_90_mock_1_inner_rmd_x8_90_1_collision_simple.stl"/>
    <mesh name="fused_component_torso_1_rmd_x8_90_mock_1_outer_rmd_x8_90_1_collision_simple" file="fused_component_torso_1_rmd_x8_90_mock_1_outer_rmd_x8_90_1_collision_simple.stl"/>
    <mesh name="full_arm_5_dof_1_lower_arm_1_dof_1_hand_1_rmd_x4_24_mock_1_inner_rmd_x4_24_1_simple" file="full_arm_5_dof_1_lower_arm_1_dof_1_hand_1_rmd_x4_24_mock_1_inner_rmd_x4_24_1_simple.stl"/>
    <mesh name="full_arm_5_dof_2_lower_arm_1_dof_1_hand_1_rmd_x4_24_mock_1_inner_rmd_x4_24_1_simple" file="full_arm_5_dof_2_lower_arm_1_dof_1_hand_1_rmd_x4_24_mock_1_inner_rmd_x4_24_1_simple.stl"/>
  </asset>
  <worldbody>
    <geom type="mesh" rgba="0.813725 0.680392 0.32549 1" mesh="fused_component_torso_1_hip_mount_1_collision_simple"/>
    <geom pos="0 -0.0160259 9.37821e-11" quat="0.612372 -0.612372 -0.353553 -0.353553" type="mesh" rgba="0.454419 0.474602 0.702397 1" mesh="fused_component_torso_1_rmd_x8_90_mock_1_outer_rmd_x8_90_1_collision_simple"/>
    <geom pos="0.131126 -0.389566 -0.0757055" quat="-0.125004 -0.856956 0.072171 -0.494764" type="mesh" rgba="0.510294 0.514216 0.506863 1" mesh="fused_component_full_arm_5_dof_2_upper_left_arm_1_rmd_x8_90_mock_1_inner_rmd_x8_90_1_collision_simple"/>
    <geom pos="0.190665 -0.42532 -0.132831" quat="-0.283467 -0.913573 0.0683872 0.283467" type="mesh" rgba="0.772059 0.868137 0.88848 1" mesh="fused_component_full_arm_5_dof_2_upper_left_arm_1_rmd_x8_90_mock_2_inner_rmd_x8_90_1_collision_simple"/>
    <geom pos="0.0458081 -0.3602 -0.0264473" quat="-0.152085 -0.445552 0.248799 0.846435" type="mesh" rgba="0.764216 0.782843 0.823529 1" mesh="fused_component_full_arm_5_dof_2_upper_left_arm_1_rmd_x4_24_mock_1_outer_rmd_x4_24_1_collision_simple"/>
    <geom pos="-0.0650819 -0.329391 0.0427712" quat="-0.422593 0.774448 0.422593 0.207513" type="mesh" rgba="0.741912 0.86201 0.930882 1" mesh="fused_component_full_arm_5_dof_2_upper_left_arm_1_rmd_x4_24_mock_2_inner_rmd_x4_24_1_collision_simple"/>
    <geom pos="0.0918711 -0.342604 -0.00307347" quat="-0.186416 0.715228 -0.336435 0.583532" type="mesh" rgba="0.682108 0.780147 0.838971 1" mesh="fused_component_full_arm_5_dof_2_lower_arm_1_dof_1_rmd_x4_24_mock_2_outer_rmd_x4_24_1_collision_simple"/>
    <geom pos="0.178285 -0.353943 -0.0255265" quat="0.715228 0.186416 -0.583532 -0.336435" type="mesh" rgba="0.768627 0.886275 0.952941 1" mesh="full_arm_5_dof_2_lower_arm_1_dof_1_hand_1_rmd_x4_24_mock_1_inner_rmd_x4_24_1_simple"/>
    <geom pos="0.225847 -0.434055 -0.110666" quat="0.140857 -0.00916181 -0.910805 0.387955" type="mesh" rgba="0.423529 0.596078 0.817647 1" mesh="fused_component_full_arm_5_dof_2_lower_arm_1_dof_1_hand_1_slide_1_collision_simple"/>
    <geom pos="0.278586 -0.293231 0.0211937" quat="0.00916181 0.140857 0.387955 0.910805" type="mesh" rgba="0.423529 0.596078 0.817647 1" mesh="fused_component_full_arm_5_dof_2_lower_arm_1_dof_1_hand_1_slide_2_collision_simple"/>
    <body name="fused_component_full_arm_5_dof_1_upper_left_arm_1_rmd_x8_90_mock_1_inner_rmd_x8_90_1" pos="-0.131126 -0.389566 0.0757055" quat="0.856956 0.125004 -0.494764 0.0721711">
      <joint name="joint_full_arm_5_dof_1_upper_left_arm_1_rmd_x8_90_mock_1_dof_x8" pos="0 0 0" axis="0 0 1" range="-3.14159 3.14159" actuatorfrcrange="-6 6"/>
      <geom type="mesh" rgba="0.510294 0.514216 0.506863 1" mesh="fused_component_full_arm_5_dof_1_upper_left_arm_1_rmd_x8_90_mock_1_inner_rmd_x8_90_1_collision_simple"/>
      <body name="fused_component_full_arm_5_dof_1_upper_left_arm_1_rmd_x8_90_mock_2_inner_rmd_x8_90_1" pos="-0.0197021 0.011375 0.087" quat="0.683013 -0.183013 -0.683013 -0.183013">
        <joint name="joint_full_arm_5_dof_1_upper_left_arm_1_rmd_x8_90_mock_2_dof_x8" pos="0 0 0" axis="0 0 1" range="-4.97738 5.3058" actuatorfrcrange="-6 6"/>
        <geom type="mesh" rgba="0.772059 0.868137 0.88848 1" mesh="fused_component_full_arm_5_dof_1_upper_left_arm_1_rmd_x8_90_mock_2_inner_rmd_x8_90_1_collision_simple"/>
        <body name="fused_component_full_arm_5_dof_1_upper_left_arm_1_rmd_x4_24_mock_1_outer_rmd_x4_24_1" pos="-0.1898 -1.96539e-09 -0.02275" quat="0.707107 1.64085e-08 -0.707107 1.64085e-08">
          <joint name="joint_full_arm_5_dof_1_upper_left_arm_1_rmd_x4_24_mock_1_dof_x4" pos="0 0 0" axis="0 0 1" range="-3.14159 3.14159" actuatorfrcrange="-6 6"/>
          <geom type="mesh" rgba="0.764216 0.782843 0.823529 1" mesh="fused_component_full_arm_5_dof_1_upper_left_arm_1_rmd_x4_24_mock_1_outer_rmd_x4_24_1_collision_simple"/>
          <body name="fused_component_full_arm_5_dof_1_upper_left_arm_1_rmd_x4_24_mock_2_inner_rmd_x4_24_1" pos="-2.94744e-10 0.009 0.134" quat="1.89469e-08 -1.89469e-08 -0.707107 0.707107">
            <joint name="joint_full_arm_5_dof_1_upper_left_arm_1_rmd_x4_24_mock_2_dof_x4" pos="0 0 0" axis="0 0 1" range="-1.44862 5.44543" actuatorfrcrange="-6 6"/>
            <geom type="mesh" rgba="0.741912 0.86201 0.930882 1" mesh="fused_component_full_arm_5_dof_1_upper_left_arm_1_rmd_x4_24_mock_2_inner_rmd_x4_24_1_collision_simple"/>
            <body name="fused_component_full_arm_5_dof_1_lower_arm_1_dof_1_rmd_x4_24_mock_2_outer_rmd_x4_24_1" pos="0.0499361 0.156003 0.00894415" quat="0.6116 -0.474292 0.524449 0.354888">
              <joint name="joint_full_arm_5_dof_1_lower_arm_1_dof_1_rmd_x4_24_mock_2_dof_x4" pos="0 0 0" axis="0 0 1" range="-3.14159 3.14159" actuatorfrcrange="-6 6"/>
              <geom type="mesh" rgba="0.682108 0.780147 0.838971 1" mesh="fused_component_full_arm_5_dof_1_lower_arm_1_dof_1_rmd_x4_24_mock_2_outer_rmd_x4_24_1_collision_simple"/>
              <geom pos="0 -4.17692e-09 0.09" quat="6.96153e-08 -1 0 0" type="mesh" rgba="0.768627 0.886275 0.952941 1" mesh="full_arm_5_dof_1_lower_arm_1_dof_1_hand_1_rmd_x4_24_mock_1_inner_rmd_x4_24_1_simple"/>
              <body name="fused_component_full_arm_5_dof_1_lower_arm_1_dof_1_hand_1_slide_1" pos="-4.64102e-09 0.1 0.167" quat="0.5 -0.5 0.5 0.5">
                <joint name="joint_full_arm_5_dof_1_lower_arm_1_dof_1_hand_1_slider_1" pos="0 0 0" axis="0 0 -1" type="slide" range="0.02 0.03" actuatorfrcrange="-6 6"/>
                <geom type="mesh" rgba="0.423529 0.596078 0.817647 1" mesh="fused_component_full_arm_5_dof_1_lower_arm_1_dof_1_hand_1_slide_1_collision_simple"/>
                <site name="target_site" pos="0.005 0.005 0.005" size="0.005" rgba="1 0 0 1"/>
              </body>
              <body name="fused_component_full_arm_5_dof_1_lower_arm_1_dof_1_hand_1_slide_2" pos="4.64102e-09 -0.1 0.167" quat="0.5 0.5 0.5 -0.5">
                <joint name="joint_full_arm_5_dof_1_lower_arm_1_dof_1_hand_1_slider_2" pos="0 0 0" axis="0 0 -1" type="slide" range="0.01 0.03" actuatorfrcrange="-6 6"/>
                <geom type="mesh" rgba="0.423529 0.596078 0.817647 1" mesh="fused_component_full_arm_5_dof_1_lower_arm_1_dof_1_hand_1_slide_2_collision_simple"/>
              </body>
            </body>
          </body>
        </body>
      </body>
    </body>

    <body name="ball_body" pos="-0.2 0 0"> <!-- 1 meter away from arm in the x-direction -->
      <geom name="red_ball" type="sphere" size="0.05" pos="0 0 0" rgba="1 0 0 1"/> <!-- radius of 0.05 meters -->
    </body>
  </worldbody>
</mujoco>
